Workbook

Sheet CAPEX CJI3
A1: WBS Element | B1: Document Date | C1: Object | D1: Cost Element | E1: Purchasing Document | F1: Value in Obj. Crcy | G1: Value TranCurr | H1: CO area currency | I1: Transaction Currency | J1: Name | K1: Ref. Fiscal Year | L1: From Period | M1: Cost element descr. | N1: Posting Date
A2: N7941/2507 | B2: 45929 | C2: N7941/2507 | D2: 6190000001 | E2: 4791010474 | F2: 1145 | G2: 1145 | H2: EUR | I2: EUR | J2: SAP BELGIUM NV/Redesign Profitability Model-_30632 | K2: 2025 | L2: 9 | M2: Purch Investment IT | N2: 45929
A3: N7941/2507 | B3: 45950 | C3: N7941/2507 | D3: 6190000001 | E3: 4791010474 | F3: 2290 | G3: 2290 | H3: EUR | I3: EUR | J3: SAP BELGIUM NV/Redesign Profitability Model-_30632 | K3: 2025 | L3: 10 | M3: Purch Investment IT | N3: 45950
A4: N7941/2507 | B4: 45961 | C4: N7941/2507 | D4: 6190000001 | F4: 10950 | G4: 10950 | H4: EUR | I4: EUR | J4: Reclass internal hours from OPEX to Capex | K4: 2025 | L4: 10 | M4: Purch Investment IT | N4: 45961
A5: N7941/2507 | B5: 45991 | C5: N7941/2507 | D5: 6190000001 | F5: 1400 | G5: 1400 | H5: EUR | I5: EUR | J5: Reclass internal hours from OPEX to Capex | K5: 2025 | L5: 11 | M5: Purch Investment IT | N5: 45991
A6: N7941/2507 | B6: 45995 | C6: N7941/2507 | D6: 6190000001 | E6: 4791010474 | F6: 2290 | G6: 2290 | H6: EUR | I6: EUR | J6: SAP BELGIUM NV/Redesign Profitability Model-_30632 | K6: 2025 | L6: 12 | M6: Purch Investment IT | N6: 45995
A7: N7941/2507 | B7: 46005 | C7: N7941/2507 | D7: 6190000001 | E7: 4791010474 | F7: 2290 | G7: 2290 | H7: EUR | I7: EUR | J7: SAP BELGIUM NV/Redesign Profitability Model-_30632 | K7: 2025 | L7: 12 | M7: Purch Investment IT | N7: 46005
A8: N7941/2507 | B8: 46022 | C8: N7941/2507 | D8: 6190000001 | F8: 800 | G8: 800 | H8: EUR | I8: EUR | J8: Reclass internal hours from OPEX to Capex | K8: 2025 | L8: 12 | M8: Purch Investment IT | N8: 46022
A9: N7941/2507 | B9: 46053 | C9: N7941/2507 | D9: 6190000001 | F9: 3300 | G9: 3300 | H9: EUR | I9: EUR | J9: Reclass internal hours from OPEX to Capex | K9: 2026 | L9: 1 | M9: Purch Investment IT | N9: 46053
A10: N7941/2507 | B10: 46081 | C10: N7941/2507 | D10: 6190000001 | F10: 3100 | G10: 3100 | H10: EUR | I10: EUR | J10: Reclass internal hours from OPEX to Capex | K10: 2026 | L10: 2 | M10: Purch Investment IT | N10: 46081
A11: N7941/2507 | B11: 46112 | C11: N7941/2507 | D11: 6190000001 | F11: 1100 | G11: 1100 | H11: EUR | I11: EUR | J11: Reclass internal hours from OPEX to Capex | K11: 2026 | L11: 3 | M11: Purch Investment IT | N11: 46112
A12: N7941/2507 | B12: 46142 | C12: N7941/2507 | D12: 6190000001 | F12: 9400 | G12: 9400 | H12: EUR | I12: EUR | J12: Reclass internal hours from OPEX to Capex | K12: 2026 | L12: 4 | M12: Purch Investment IT | N12: 46142
A13: N7941/2507 | B13: 46173 | C13: N7941/2507 | D13: 6190000001 | F13: 3400 | G13: 3400 | H13: EUR | I13: EUR | J13: Reclass internal hours from OPEX to Capex | K13: 2026 | L13: 5 | M13: Purch Investment IT | N13: 46173
A14: N7941/2507 | B14: 46203 | C14: N7941/2507 | D14: 6190000001 | F14: 6175.28 | G14: 6175.28 | H14: EUR | I14: EUR | J14: Reclass internal hours from OPEX to Capex | K14: 2026 | L14: 6 | M14: Purch Investment IT | N14: 46203
A15: N7941/2507 | B15: 46219 | C15: N7941/2507 | D15: 6190000001 | E15: 4791010474 | F15: 2290 | G15: 2290 | H15: EUR | I15: EUR | J15: SAP BELGIUM N/Redesign Profitability Model-_306324 | K15: 2026 | L15: 7 | M15: Purch Investment IT | N15: 46219
A16: N7941/2507 | B16: 46234 | C16: N7941/2507 | D16: 6190000001 | F16: 3774.72 | G16: 3774.72 | H16: EUR | I16: EUR | J16: Reclass internal hours from OPEX to Capex | K16: 2026 | L16: 7 | M16: Purch Investment IT | N16: 46234
A17: N7941/2507 | B17: 46265 | C17: N7941/2507 | D17: 6190000001 | F17: 14668 | G17: 14668 | H17: EUR | I17: EUR | J17: Reclass internal hours from OPEX to Capex | K17: 2026 | L17: 8 | M17: Purch Investment IT | N17: 46265
A18: N7941/2507 | F18: 68373 | G18: 68373 | I18: EUR
A19: O6300/2603 | B19: 46239 | C19: O6300/2603 | D19: 6190000001 | E19: 4631069083 | F19: 571.85 | G19: 571.85 | H19: EUR | I19: EUR | J19: COMPUTACENTER NV/FortiGate switch controller | K19: 2026 | L19: 8 | M19: Purch Investment IT | N19: 46258
A20: O6300/2603 | F20: 571.85 | G20: 571.85 | I20: EUR
A21: O7941/2513 | B21: 45961 | C21: O7941/2513 | D21: 6190000001 | F21: 3800 | G21: 3800 | H21: EUR | I21: EUR | J21: Reclass internal hours from OPEX to Capex | K21: 2025 | L21: 10 | M21: Purch Investment IT | N21: 45961
A22: O7941/2513 | B22: 45991 | C22: O7941/2513 | D22: 6190000001 | F22: 1500 | G22: 1500 | H22: EUR | I22: EUR | J22: Reclass internal hours from OPEX to Capex | K22: 2025 | L22: 11 | M22: Purch Investment IT | N22: 45991
A23: O7941/2513 | B23: 45993 | C23: O7941/2513 | D23: 6190000001 | E23: 4791010526 | F23: 60000 | G23: 60000 | H23: EUR | I23: EUR | J23: PLANISWARE BELGIUM SRL/2025-Symphony implementatio | K23: 2025 | L23: 12 | M23: Purch Investment IT | N23: 45993
A24: O7941/2513 | B24: 45993 | C24: O7941/2513 | D24: 6190000001 | E24: 4791010526 | F24: 15000 | G24: 15000 | H24: EUR | I24: EUR | J24: PLANISWARE BELGIUM SRL/2025-licences | K24: 2025 | L24: 12 | M24: Purch Investment IT | N24: 45993
A25: O7941/2513 | B25: 46006 | C25: O7941/2513 | D25: 6190000001 | E25: 4791010526 | F25: 40000 | G25: 40000 | H25: EUR | I25: EUR | J25: PLANISWARE BELGIUM SRL/2025-Symphony implementatio | K25: 2025 | L25: 12 | M25: Purch Investment IT | N25: 46006
A26: O7941/2513 | B26: 46006 | C26: O7941/2513 | D26: 6190000001 | E26: 4791010606 | F26: 11760 | G26: 11760 | H26: EUR | I26: EUR | J26: TEAM4P/2025 implementation of Planisware softw | K26: 2025 | L26: 12 | M26: Purch Investment IT | N26: 46006
A27: O7941/2513 | B27: 46006 | C27: O7941/2513 | D27: 6190000001 | E27: 4791010526 | F27: 1687.8 | G27: 1687.8 | H27: EUR | I27: EUR | J27: PLANISWARE BELGIUM SRL/2025-essential travel | K27: 2025 | L27: 12 | M27: Purch Investment IT | N27: 46006
A28: O7941/2513 | B28: 46022 | C28: O7941/2513 | D28: 7405000000 | F28: 17548 | G28: 17548 | H28: EUR | I28: EUR | J28: 7941 - Engineering - Symphony Project | K28: 2025 | L28: 12 | M28: IC-Technical assistance & man fees | N28: 46022
A29: O7941/2513 | B29: 46022 | C29: O7941/2513 | D29: 6190000001 | F29: 12700 | G29: 12700 | H29: EUR | I29: EUR | J29: Reclass internal hours from OPEX to Capex | K29: 2025 | L29: 12 | M29: Purch Investment IT | N29: 46022
A30: O7941/2513 | B30: 46022 | C30: O7941/2513 | D30: 6405000000 | F30: 17548 | G30: 17548 | H30: EUR | I30: EUR | J30: 7941 - Engineering - Symphony Project | K30: 2025 | L30: 12 | M30: IC Oth oper chgs Tech assist & man fees | N30: 46022
A31: O7941/2513 | B31: 46053 | C31: O7941/2513 | D31: 7405000000 | F31: 26475 | G31: 26475 | H31: EUR | I31: EUR | J31: 7941 - Engineering - Symphony Project | K31: 2026 | L31: 1 | M31: IC-Technical assistance & man fees | N31: 46053
A32: O7941/2513 | B32: 46053 | C32: O7941/2513 | D32: 7405000000 | F32: 2675 | G32: 2675 | H32: EUR | I32: EUR | J32: 7941 - Engineering - Symphony Project | K32: 2026 | L32: 1 | M32: IC-Technical assistance & man fees | N32: 46053
A33: O7941/2513 | B33: 46053 | C33: O7941/2513 | D33: 6190000001 | F33: 1800 | G33: 1800 | H33: EUR | I33: EUR | J33: Reclass internal hours from OPEX to Capex | K33: 2026 | L33: 1 | M33: Purch Investment IT | N33: 46053
A34: O7941/2513 | B34: 46053 | C34: O7941/2513 | D34: 6190000001 | F34: 2675 | G34: 2675 | H34: EUR | I34: EUR | J34: Reclass | K34: 2026 | L34: 1 | M34: Purch Investment IT | N34: 46053
A35: O7941/2513 | B35: 46063 | C35: O7941/2513 | D35: 6190000001 | E35: 4791010606 | F35: 3570 | G35: 3570 | H35: EUR | I35: EUR | J35: TEAM4P/2026 implementation of Planisware softw | K35: 2026 | L35: 2 | M35: Purch Investment IT | N35: 46063
A36: O7941/2513 | B36: 46066 | C36: O7941/2513 | D36: 7405000000 | F36: 7543.5 | G36: 7543.5 | H36: EUR | I36: EUR | J36: 7941 - Engineering - Symphony Project | K36: 2026 | L36: 2 | M36: IC-Technical assistance & man fees | N36: 46066
A37: O7941/2513 | B37: 46081 | C37: O7941/2513 | D37: 6190000001 | F37: 5085 | G37: 5085 | H37: EUR | I37: EUR | J37: Reclass internal hours from OPEX to Capex | K37: 2026 | L37: 2 | M37: Purch Investment IT | N37: 46081
A38: O7941/2513 | B38: 46083 | C38: O7941/2513 | D38: 6190000001 | E38: 4791010606 | F38: 5600 | G38: 5600 | H38: EUR | I38: EUR | J38: TEAM4P/2026 implementation of Planisware softw | K38: 2026 | L38: 3 | M38: Purch Investment IT | N38: 46083
A39: O7941/2513 | B39: 46081 | C39: O7941/2513 | D39: 6190000001 | F39: 7543.5 | G39: 7543.5 | H39: EUR | I39: EUR | J39: Reclass | K39: 2026 | L39: 2 | M39: Purch Investment IT | N39: 46081
A40: O7941/2513 | B40: 46092 | C40: O7941/2513 | D40: 6190000001 | E40: 4791010688 | F40: 15000 | G40: 15000 | H40: EUR | I40: EUR | J40: PLANISWARE BELGIUM SRL/2026-symphony licences | K40: 2026 | L40: 3 | M40: Purch Investment IT | N40: 46092
...

Sheet OPEX CJI3
A1: WBS Element | B1: Document Date | C1: Object | D1: Cost Element | E1: Purchasing Document | F1: Value in Obj. Crcy | G1: Value TranCurr | H1: CO area currency | I1: Transaction Currency | J1: Name | K1: Ref. Fiscal Year | L1: From Period | M1: Cost element descr. | N1: Posting Date
A2: C7941/1896/1 | B2: 45447 | C2: C7941/1896/1 | D2: 7405000000 | F2: 30000 | G2: 30000 | H2: EUR | I2: EUR | L2: 5 | M2: IC-Technical assistance & man fees | N2: 45443
A3: C7941/1896/1 | B3: 45432 | C3: C7941/1896/1 | D3: 7405000000 | F3: -30000 | G3: -30000 | H3: EUR | I3: EUR | K3: 2024 | L3: 5 | M3: IC-Technical assistance & man fees | N3: 45432
A4: Period 5 | F4: 0 | G4: 0 | I4: EUR
A5: C7941/1896/1 | B5: 45475 | C5: C7941/1896/1 | D5: 7405000000 | F5: 30000 | G5: 30000 | H5: EUR | I5: EUR | L5: 6 | M5: IC-Technical assistance & man fees | N5: 45473
A6: C7941/1896/1 | B6: 45462 | C6: C7941/1896/1 | D6: 7405000000 | F6: -8000 | G6: -8000 | H6: EUR | I6: EUR | K6: 2024 | L6: 6 | M6: IC-Technical assistance & man fees | N6: 45462
A7: C7941/1896/1 | B7: 45462 | C7: C7941/1896/1 | D7: 7405000000 | F7: -22000 | G7: -22000 | H7: EUR | I7: EUR | K7: 2024 | L7: 6 | M7: IC-Technical assistance & man fees | N7: 45462
A8: Period 6 | F8: 0 | G8: 0 | I8: EUR
A9: C7941/1896/1 | B9: 45264 | C9: C7941/1896/1 | D9: 7405000000 | F9: 17000 | G9: 17000 | H9: EUR | I9: EUR | L9: 11 | M9: IC-Technical assistance & man fees | N9: 45260
A10: C7941/1896/1 | B10: 45247 | C10: C7941/1896/1 | D10: 7405000000 | F10: -17000 | G10: -17000 | H10: EUR | I10: EUR | K10: 2023 | L10: 11 | M10: IC-Technical assistance & man fees | N10: 45247
A11: Period 11 | F11: 0 | G11: 0 | I11: EUR
A12: C7941/1896/1 | B12: 44930 | C12: C7941/1896/1 | D12: 7405000000 | F12: 68000 | G12: 68000 | H12: EUR | I12: EUR | L12: 12 | M12: IC-Technical assistance & man fees | N12: 44926
A13: C7941/1896/1 | B13: 45295 | C13: C7941/1896/1 | D13: 7405000000 | F13: 34000 | G13: 34000 | H13: EUR | I13: EUR | L13: 12 | M13: IC-Technical assistance & man fees | N13: 45291
A14: C7941/1896/1 | B14: 44914 | C14: C7941/1896/1 | D14: 7405000000 | F14: -17000 | G14: -17000 | H14: EUR | I14: EUR | K14: 2022 | L14: 12 | M14: IC-Technical assistance & man fees | N14: 44914
A15: C7941/1896/1 | B15: 44914 | C15: C7941/1896/1 | D15: 7405000000 | F15: -17000 | G15: -17000 | H15: EUR | I15: EUR | K15: 2022 | L15: 12 | M15: IC-Technical assistance & man fees | N15: 44914
A16: C7941/1896/1 | B16: 44915 | C16: C7941/1896/1 | D16: 7405000000 | F16: -17000 | G16: -17000 | H16: EUR | I16: EUR | K16: 2022 | L16: 12 | M16: IC-Technical assistance & man fees | N16: 44915
A17: C7941/1896/1 | B17: 44915 | C17: C7941/1896/1 | D17: 7405000000 | F17: -17000 | G17: -17000 | H17: EUR | I17: EUR | K17: 2022 | L17: 12 | M17: IC-Technical assistance & man fees | N17: 44915
A18: C7941/1896/1 | B18: 45271 | C18: C7941/1896/1 | D18: 7405000000 | F18: -17000 | G18: -17000 | H18: EUR | I18: EUR | K18: 2023 | L18: 12 | M18: IC-Technical assistance & man fees | N18: 45271
A19: C7941/1896/1 | B19: 45271 | C19: C7941/1896/1 | D19: 7405000000 | F19: -17000 | G19: -17000 | H19: EUR | I19: EUR | K19: 2023 | L19: 12 | M19: IC-Technical assistance & man fees | N19: 45271
A20: Period 12 | F20: 0 | G20: 0 | I20: EUR
A21: C7941/1896/1 | F21: 0 | G21: 0 | I21: EUR
A22: C7941/1896/2/1 | B22: 44596 | C22: C7941/1896/2/1 | D22: 6133000035 | F22: -1500 | G22: -1500 | H22: EUR | I22: EUR | L22: 1 | M22: Service IT | N22: 44592
A23: C7941/1896/2/1 | B23: 44960 | C23: C7941/1896/2/1 | D23: 6133000035 | F23: -2900 | G23: -2900 | H23: EUR | I23: EUR | L23: 1 | M23: Service IT | N23: 44957
A24: C7941/1896/2/1 | B24: 45324 | C24: C7941/1896/2/1 | D24: 6133000035 | F24: -200 | G24: -200 | H24: EUR | I24: EUR | L24: 1 | M24: Service IT | N24: 45322
A25: C7941/1896/2/1 | B25: 44561 | C25: C7941/1896/2/1 | D25: 6133000035 | F25: -400 | G25: -400 | H25: EUR | I25: EUR | J25: App Mandays Dec 2021 | K25: 2022 | L25: 1 | M25: Service IT | N25: 44562
A26: C7941/1896/2/1 | B26: 44592 | C26: C7941/1896/2/1 | D26: 6133000035 | F26: 1900 | G26: 1900 | H26: EUR | I26: EUR | J26: App Mandays Jan 2022 | K26: 2022 | L26: 1 | M26: Service IT | N26: 44592
A27: C7941/1896/2/1 | B27: 44957 | C27: C7941/1896/2/1 | D27: 6133000035 | F27: 2900 | G27: 2900 | H27: EUR | I27: EUR | J27: App Mandays Jan 2023 | K27: 2023 | L27: 1 | M27: Service IT | N27: 44957
A28: C7941/1896/2/1 | B28: 45322 | C28: C7941/1896/2/1 | D28: 6133000035 | F28: 200 | G28: 200 | H28: EUR | I28: EUR | J28: IT Business Solutions Mandays Jan 2024 | K28: 2024 | L28: 1 | M28: Service IT | N28: 45322
A29: Period 1 | F29: 0 | G29: 0 | I29: EUR
A30: C7941/1896/2/1 | B30: 44623 | C30: C7941/1896/2/1 | D30: 6133000035 | F30: -3800 | G30: -3800 | H30: EUR | I30: EUR | L30: 2 | M30: Service IT | N30: 44620
A31: C7941/1896/2/1 | B31: 44988 | C31: C7941/1896/2/1 | D31: 6133000035 | F31: -1600 | G31: -1600 | H31: EUR | I31: EUR | L31: 2 | M31: Service IT | N31: 44985
A32: C7941/1896/2/1 | B32: 45356 | C32: C7941/1896/2/1 | D32: 6133000035 | F32: -9500 | G32: -9500 | H32: EUR | I32: EUR | L32: 2 | M32: Service IT | N32: 45351
A33: C7941/1896/2/1 | B33: 44592 | C33: C7941/1896/2/1 | D33: 6133000035 | F33: -1900 | G33: -1900 | H33: EUR | I33: EUR | J33: App Mandays Jan 2022 | K33: 2022 | L33: 2 | M33: Service IT | N33: 44593
A34: C7941/1896/2/1 | B34: 44620 | C34: C7941/1896/2/1 | D34: 6133000035 | F34: 5100 | G34: 5100 | H34: EUR | I34: EUR | J34: App Mandays Feb 2022 | K34: 2022 | L34: 2 | M34: Service IT | N34: 44620
A35: C7941/1896/2/1 | B35: 44620 | C35: C7941/1896/2/1 | D35: 6133000035 | F35: 600 | G35: 600 | H35: EUR | I35: EUR | J35: Techn Mandays Feb 2022 | K35: 2022 | L35: 2 | M35: Service IT | N35: 44620
A36: C7941/1896/2/1 | B36: 44957 | C36: C7941/1896/2/1 | D36: 6133000035 | F36: -2900 | G36: -2900 | H36: EUR | I36: EUR | J36: App Mandays Jan 2023 | K36: 2023 | L36: 2 | M36: Service IT | N36: 44958
A37: C7941/1896/2/1 | B37: 44985 | C37: C7941/1896/2/1 | D37: 6133000035 | F37: 4500 | G37: 4500 | H37: EUR | I37: EUR | J37: App Mandays Feb 2023 | K37: 2023 | L37: 2 | M37: Service IT | N37: 44985
A38: C7941/1896/2/1 | B38: 45322 | C38: C7941/1896/2/1 | D38: 6133000035 | F38: -200 | G38: -200 | H38: EUR | I38: EUR | J38: IT Business Solutions Mandays Jan 2024 | K38: 2024 | L38: 2 | M38: Service IT | N38: 45323
A39: C7941/1896/2/1 | B39: 45351 | C39: C7941/1896/2/1 | D39: 6133000035 | F39: 9700 | G39: 9700 | H39: EUR | I39: EUR | J39: IT Business Solutions Mandays Feb 2024 | K39: 2024 | L39: 2 | M39: Service IT | N39: 45351
A40: Period 2 | F40: 0 | G40: 0 | I40: EUR
...

Sheet CAPEX Tables
A1: CAPEX Spend Overview
A2: Project and vendor spend from Capex CJI3 | Fiscal years 2025–2026
A3: Classification: Internal Reclass includes descriptions containing ‘Reclass internal hours’; External includes transactions with a Purchasing Document; Other includes remaining non-PO CAPEX postings after excluding WBS-correction transfer rows and duplicate 6405 intercompany entries. For O7941/2513, 7405 charges before the March 2026 correction period are also excluded. Subtotal rows are excluded.
A5: Total Spend | B5: =SUM(CapexProjectSpend[Grand Total]) -> 7830293.7 | D5: Internal Reclass | E5: =SUM(CapexProjectSpend[2025 Internal Reclass])+SUM(CapexProjectSpend[2026 Internal Reclass]) -> 2396751.7 | G5: External | H5: =SUM(CapexProjectSpend[2025 External])+SUM(CapexProjectSpend[2026 External]) -> 2492605.5 | J5: Other | K5: =SUM(CapexProjectSpend[2025 Other])+SUM(CapexProjectSpend[2026 Other]) -> 2312831.2
A6: PROJECT SPEND BY YEAR AND CLASSIFICATION
A7: CAPEX WBS | B7: 2025 Internal Reclass | C7: 2025 External | D7: 2025 Other | E7: 2025 Total | F7: 2026 Internal Reclass | G7: 2026 External | H7: 2026 Other | I7: 2026 Total | J7: Grand Total | K7: Latest Posting | L7: Transactions | M7: PO Lines | N7: Currency | O7: Project Budget
A8: N7941/2507 | B8: =SUMIFS('[1]Capex CJI3'!$F$2:$F$433,'[1]Capex CJI3'!$A$2:$A$433,$A8,'[1]Capex CJI3'!$K$2:$K$433,2025,'[1]Capex CJI3'!$J$2:$J$433,"*Reclass internal hours*") -> 13150 | C8: {=SUMPRODUCT(('[1]Capex CJI3'!$A$2:$A$433=$A8)*(IFERROR(VALUE('[1]Capex CJI3'!$K$2:$K$433),0)=2025)*(LEN('[1]Capex CJI3'!$E$2:$E$433)>0)*ISERROR(SEARCH("Reclass internal hours",'[1]Capex CJI3'!$J$2:$J$433))*IFERROR(VALUE('[1]Capex CJI3'!$F$2:$F$433),0))} -> 8015 | D8: {=SUMPRODUCT(('[1]Capex CJI3'!$A$2:$A$433=$A8)*(IFERROR(VALUE('[1]Capex CJI3'!$K$2:$K$433),0)=2025)*(LEN('[1]Capex CJI3'!$E$2:$E$433)=0)*ISERROR(SEARCH("Reclass internal hours",'[1]Capex CJI3'!$J$2:$J$433))*ISERROR(SEARCH("WBS Correction",'[1]Capex CJI3'!$J$2:$J$433))*('[1]Capex CJI3'!$D$2:$D$433<>"6405000000")*IFERROR(VALUE('[1]Capex CJI3'!$F$2:$F$433),0))} -> 0 | E8: =SUM(B8:D8) -> 21165 | F8: =SUMIFS('[1]Capex CJI3'!$F$2:$F$433,'[1]Capex CJI3'!$A$2:$A$433,$A8,'[1]Capex CJI3'!$K$2:$K$433,2026,'[1]Capex CJI3'!$J$2:$J$433,"*Reclass internal hours*") -> 44918 | G8: {=SUMPRODUCT(('[1]Capex CJI3'!$A$2:$A$433=$A8)*(IFERROR(VALUE('[1]Capex CJI3'!$K$2:$K$433),0)=2026)*(LEN('[1]Capex CJI3'!$E$2:$E$433)>0)*ISERROR(SEARCH("Reclass internal hours",'[1]Capex CJI3'!$J$2:$J$433))*IFERROR(VALUE('[1]Capex CJI3'!$F$2:$F$433),0))-IF($A8="O7941/2517",'[1]Capex CJI3'!$F$124,0)-IF($A8="O7941/2613",'[1]Capex CJI3'!$F$313,0)} -> 2290 | H8: {=SUMPRODUCT(('[1]Capex CJI3'!$A$2:$A$433=$A8)*(IFERROR(VALUE('[1]Capex CJI3'!$K$2:$K$433),0)=2026)*(LEN('[1]Capex CJI3'!$E$2:$E$433)=0)*ISERROR(SEARCH("Reclass internal hours",'[1]Capex CJI3'!$J$2:$J$433))*ISERROR(SEARCH("WBS Correction",'[1]Capex CJI3'!$J$2:$J$433))*('[1]Capex CJI3'!$D$2:$D$433<>"6405000000")*((($A8<>"O7941/2513")+('[1]Capex CJI3'!$D$2:$D$433<>"7405000000")+(IFERROR(VALUE('[1]Capex CJI3'!$L$2:$L$433),0)>=3))>0)*IFERROR(VALUE('[1]Capex CJI3'!$F$2:$F$433),0))-IF($A8="O7941/2517",'[1]Capex CJI3'!$F$132,0)-IF($A8="O9100/2601",'[1]Capex CJI3'!$F$429,0)} -> 0 | I8: =SUM(F8:H8) -> 47208 | J8: =E8+I8 -> 68373 | K8: 46265 | L8: {=SUMPRODUCT(('[1]Capex CJI3'!$A$2:$A$433=$A8)*(IFERROR(VALUE('[1]Capex CJI3'!$K$2:$K$433),0)>0)*((ISNUMBER(SEARCH("Reclass internal hours",'[1]Capex CJI3'!$J$2:$J$433)))+((LEN('[1]Capex CJI3'!$E$2:$E$433)>0)*ISERROR(SEARCH("Reclass internal hours",'[1]Capex CJI3'!$J$2:$J$433)))+((LEN('[1]Capex CJI3'!$E$2:$E$433)=0)*ISERROR(SEARCH("Reclass internal hours",'[1]Capex CJI3'!$J$2:$J$433))*ISERROR(SEARCH("WBS Correction",'[1]Capex CJI3'!$J$2:$J$433))*('[1]Capex CJI3'!$D$2:$D$433<>"6405000000"))>0))-IF($A8="O7941/2517",2,0)-IF($A8="O7941/2613",1,0)-IF($A8="O9100/2601",1,0)-IF($A8="O7941/2513",4,0)} -> 16 | M8: {=SUMPRODUCT(('[1]Capex CJI3'!$A$2:$A$433=$A8)*(IFERROR(VALUE('[1]Capex CJI3'!$K$2:$K$433),0)>0)*(LEN('[1]Capex CJI3'!$E$2:$E$433)>0)*ISERROR(SEARCH("Reclass internal hours",'[1]Capex CJI3'!$J$2:$J$433)))-IF($A8="O7941/2517",1,0)-IF($A8="O7941/2613",1,0)} -> 5 | N8: EUR | O8: 140000
A9: O6300/2603 | B9: =SUMIFS('[1]Capex CJI3'!$F$2:$F$433,'[1]Capex CJI3'!$A$2:$A$433,$A9,'[1]Capex CJI3'!$K$2:$K$433,2025,'[1]Capex CJI3'!$J$2:$J$433,"*Reclass internal hours*") -> 0 | C9: {=SUMPRODUCT(('[1]Capex CJI3'!$A$2:$A$433=$A9)*(IFERROR(VALUE('[1]Capex CJI3'!$K$2:$K$433),0)=2025)*(LEN('[1]Capex CJI3'!$E$2:$E$433)>0)*ISERROR(SEARCH("Reclass internal hours",'[1]Capex CJI3'!$J$2:$J$433))*IFERROR(VALUE('[1]Capex CJI3'!$F$2:$F$433),0))} -> 0 | D9: {=SUMPRODUCT(('[1]Capex CJI3'!$A$2:$A$433=$A9)*(IFERROR(VALUE('[1]Capex CJI3'!$K$2:$K$433),0)=2025)*(LEN('[1]Capex CJI3'!$E$2:$E$433)=0)*ISERROR(SEARCH("Reclass internal hours",'[1]Capex CJI3'!$J$2:$J$433))*ISERROR(SEARCH("WBS Correction",'[1]Capex CJI3'!$J$2:$J$433))*('[1]Capex CJI3'!$D$2:$D$433<>"6405000000")*IFERROR(VALUE('[1]Capex CJI3'!$F$2:$F$433),0))} -> 0 | E9: =SUM(B9:D9) -> 0 | F9: =SUMIFS('[1]Capex CJI3'!$F$2:$F$433,'[1]Capex CJI3'!$A$2:$A$433,$A9,'[1]Capex CJI3'!$K$2:$K$433,2026,'[1]Capex CJI3'!$J$2:$J$433,"*Reclass internal hours*") -> 0 | G9: {=SUMPRODUCT(('[1]Capex CJI3'!$A$2:$A$433=$A9)*(IFERROR(VALUE('[1]Capex CJI3'!$K$2:$K$433),0)=2026)*(LEN('[1]Capex CJI3'!$E$2:$E$433)>0)*ISERROR(SEARCH("Reclass internal hours",'[1]Capex CJI3'!$J$2:$J$433))*IFERROR(VALUE('[1]Capex CJI3'!$F$2:$F$433),0))-IF($A9="O7941/2517",'[1]Capex CJI3'!$F$124,0)-IF($A9="O7941/2613",'[1]Capex CJI3'!$F$313,0)} -> 571.85 | H9: {=SUMPRODUCT(('[1]Capex CJI3'!$A$2:$A$433=$A9)*(IFERROR(VALUE('[1]Capex CJI3'!$K$2:$K$433),0)=2026)*(LEN('[1]Capex CJI3'!$E$2:$E$433)=0)*ISERROR(SEARCH("Reclass internal hours",'[1]Capex CJI3'!$J$2:$J$433))*ISERROR(SEARCH("WBS Correction",'[1]Capex CJI3'!$J$2:$J$433))*('[1]Capex CJI3'!$D$2:$D$433<>"6405000000")*((($A9<>"O7941/2513")+('[1]Capex CJI3'!$D$2:$D$433<>"7405000000")+(IFERROR(VALUE('[1]Capex CJI3'!$L$2:$L$433),0)>=3))>0)*IFERROR(VALUE('[1]Capex CJI3'!$F$2:$F$433),0))-IF($A9="O7941/2517",'[1]Capex CJI3'!$F$132,0)-IF($A9="O9100/2601",'[1]Capex CJI3'!$F$429,0)} -> 0 | I9: =SUM(F9:H9) -> 571.85 | J9: =E9+I9 -> 571.85 | K9: 46258 | L9: {=SUMPRODUCT(('[1]Capex CJI3'!$A$2:$A$433=$A9)*(IFERROR(VALUE('[1]Capex CJI3'!$K$2:$K$433),0)>0)*((ISNUMBER(SEARCH("Reclass internal hours",'[1]Capex CJI3'!$J$2:$J$433)))+((LEN('[1]Capex CJI3'!$E$2:$E$433)>0)*ISERROR(SEARCH("Reclass internal hours",'[1]Capex CJI3'!$J$2:$J$433)))+((LEN('[1]Capex CJI3'!$E$2:$E$433)=0)*ISERROR(SEARCH("Reclass internal hours",'[1]Capex CJI3'!$J$2:$J$433))*ISERROR(SEARCH("WBS Correction",'[1]Capex CJI3'!$J$2:$J$433))*('[1]Capex CJI3'!$D$2:$D$433<>"6405000000"))>0))-IF($A9="O7941/2517",2,0)-IF($A9="O7941/2613",1,0)-IF($A9="O9100/2601",1,0)-IF($A9="O7941/2513",4,0)} -> 1 | M9: {=SUMPRODUCT(('[1]Capex CJI3'!$A$2:$A$433=$A9)*(IFERROR(VALUE('[1]Capex CJI3'!$K$2:$K$433),0)>0)*(LEN('[1]Capex CJI3'!$E$2:$E$433)>0)*ISERROR(SEARCH("Reclass internal hours",'[1]Capex CJI3'!$J$2:$J$433)))-IF($A9="O7941/2517",1,0)-IF($A9="O7941/2613",1,0)} -> 1 | N9: EUR | O9: 54700
A10: O7941/2513 | B10: =SUMIFS('[1]Capex CJI3'!$F$2:$F$433,'[1]Capex CJI3'!$A$2:$A$433,$A10,'[1]Capex CJI3'!$K$2:$K$433,2025,'[1]Capex CJI3'!$J$2:$J$433,"*Reclass internal hours*") -> 18000 | C10: {=SUMPRODUCT(('[1]Capex CJI3'!$A$2:$A$433=$A10)*(IFERROR(VALUE('[1]Capex CJI3'!$K$2:$K$433),0)=2025)*(LEN('[1]Capex CJI3'!$E$2:$E$433)>0)*ISERROR(SEARCH("Reclass internal hours",'[1]Capex CJI3'!$J$2:$J$433))*IFERROR(VALUE('[1]Capex CJI3'!$F$2:$F$433),0))} -> 128447.8 | D10: {=SUMPRODUCT(('[1]Capex CJI3'!$A$2:$A$433=$A10)*(IFERROR(VALUE('[1]Capex CJI3'!$K$2:$K$433),0)=2025)*(LEN('[1]Capex CJI3'!$E$2:$E$433)=0)*ISERROR(SEARCH("Reclass internal hours",'[1]Capex CJI3'!$J$2:$J$433))*ISERROR(SEARCH("WBS Correction",'[1]Capex CJI3'!$J$2:$J$433))*('[1]Capex CJI3'!$D$2:$D$433<>"6405000000")*IFERROR(VALUE('[1]Capex CJI3'!$F$2:$F$433),0))} -> 17548 | E10: =SUM(B10:D10) -> 163995.8 | F10: =SUMIFS('[1]Capex CJI3'!$F$2:$F$433,'[1]Capex CJI3'!$A$2:$A$433,$A10,'[1]Capex CJI3'!$K$2:$K$433,2026,'[1]Capex CJI3'!$J$2:$J$433,"*Reclass internal hours*") -> 48690 | G10: {=SUMPRODUCT(('[1]Capex CJI3'!$A$2:$A$433=$A10)*(IFERROR(VALUE('[1]Capex CJI3'!$K$2:$K$433),0)=2026)*(LEN('[1]Capex CJI3'!$E$2:$E$433)>0)*ISERROR(SEARCH("Reclass internal hours",'[1]Capex CJI3'!$J$2:$J$433))*IFERROR(VALUE('[1]Capex CJI3'!$F$2:$F$433),0))-IF($A10="O7941/2517",'[1]Capex CJI3'!$F$124,0)-IF($A10="O7941/2613",'[1]Capex CJI3'!$F$313,0)} -> 188080.05 | H10: {=SUMPRODUCT(('[1]Capex CJI3'!$A$2:$A$433=$A10)*(IFERROR(VALUE('[1]Capex CJI3'!$K$2:$K$433),0)=2026)*(LEN('[1]Capex CJI3'!$E$2:$E$433)=0)*ISERROR(SEARCH("Reclass internal hours",'[1]Capex CJI3'!$J$2:$J$433))*ISERROR(SEARCH("WBS Correction",'[1]Capex CJI3'!$J$2:$J$433))*('[1]Capex CJI3'!$D$2:$D$433<>"6405000000")*((($A10<>"O7941/2513")+('[1]Capex CJI3'!$D$2:$D$433<>"7405000000")+(IFERROR(VALUE('[1]Capex CJI3'!$L$2:$L$433),0)>=3))>0)*IFERROR(VALUE('[1]Capex CJI3'!$F$2:$F$433),0))-IF($A10="O7941/2517",'[1]Capex CJI3'!$F$132,0)-IF($A10="O9100/2601",'[1]Capex CJI3'!$F$429,0)} -> 93999.5 | I10: =SUM(F10:H10) -> 330769.55 | J10: =E10+I10 -> 494765.35 | K10: 46269 | L10: {=SUMPRODUCT(('[1]Capex CJI3'!$A$2:$A$433=$A10)*(IFERROR(VALUE('[1]Capex CJI3'!$K$2:$K$433),0)>0)*((ISNUMBER(SEARCH("Reclass internal hours",'[1]Capex CJI3'!$J$2:$J$433)))+((LEN('[1]Capex CJI3'!$E$2:$E$433)>0)*ISERROR(SEARCH("Reclass internal hours",'[1]Capex CJI3'!$J$2:$J$433)))+((LEN('[1]Capex CJI3'!$E$2:$E$433)=0)*ISERROR(SEARCH("Reclass internal hours",'[1]Capex CJI3'!$J$2:$J$433))*ISERROR(SEARCH("WBS Correction",'[1]Capex CJI3'!$J$2:$J$433))*('[1]Capex CJI3'!$D$2:$D$433<>"6405000000"))>0))-IF($A10="O7941/2517",2,0)-IF($A10="O7941/2613",1,0)-IF($A10="O9100/2601",1,0)-IF($A10="O7941/2513",4,0)} -> 40 | M10: {=SUMPRODUCT(('[1]Capex CJI3'!$A$2:$A$433=$A10)*(IFERROR(VALUE('[1]Capex CJI3'!$K$2:$K$433),0)>0)*(LEN('[1]Capex CJI3'!$E$2:$E$433)>0)*ISERROR(SEARCH("Reclass internal hours",'[1]Capex CJI3'!$J$2:$J$433)))-IF($A10="O7941/2517",1,0)-IF($A10="O7941/2613",1,0)} -> 23 | N10: EUR | O10: 585000
A11: O7941/2517 | B11: =SUMIFS('[1]Capex CJI3'!$F$2:$F$433,'[1]Capex CJI3'!$A$2:$A$433,$A11,'[1]Capex CJI3'!$K$2:$K$433,2025,'[1]Capex CJI3'!$J$2:$J$433,"*Reclass internal hours*") -> 2900 | C11: {=SUMPRODUCT(('[1]Capex CJI3'!$A$2:$A$433=$A11)*(IFERROR(VALUE('[1]Capex CJI3'!$K$2:$K$433),0)=2025)*(LEN('[1]Capex CJI3'!$E$2:$E$433)>0)*ISERROR(SEARCH("Reclass internal hours",'[1]Capex CJI3'!$J$2:$J$433))*IFERROR(VALUE('[1]Capex CJI3'!$F$2:$F$433),0))} -> 121088 | D11: {=SUMPRODUCT(('[1]Capex CJI3'!$A$2:$A$433=$A11)*(IFERROR(VALUE('[1]Capex CJI3'!$K$2:$K$433),0)=2025)*(LEN('[1]Capex CJI3'!$E$2:$E$433)=0)*ISERROR(SEARCH("Reclass internal hours",'[1]Capex CJI3'!$J$2:$J$433))*ISERROR(SEARCH("WBS Correction",'[1]Capex CJI3'!$J$2:$J$433))*('[1]Capex CJI3'!$D$2:$D$433<>"6405000000")*IFERROR(VALUE('[1]Capex CJI3'!$F$2:$F$433),0))} -> 89012 | E11: =SUM(B11:D11) -> 213000 | F11: =SUMIFS('[1]Capex CJI3'!$F$2:$F$433,'[1]Capex CJI3'!$A$2:$A$433,$A11,'[1]Capex CJI3'!$K$2:$K$433,2026,'[1]Capex CJI3'!$J$2:$J$433,"*Reclass internal hours*") -> 79238 | G11: {=SUMPRODUCT(('[1]Capex CJI3'!$A$2:$A$433=$A11)*(IFERROR(VALUE('[1]Capex CJI3'!$K$2:$K$433),0)=2026)*(LEN('[1]Capex CJI3'!$E$2:$E$433)>0)*ISERROR(SEARCH("Reclass internal hours",'[1]Capex CJI3'!$J$2:$J$433))*IFERROR(VALUE('[1]Capex CJI3'!$F$2:$F$433),0))-IF($A11="O7941/2517",'[1]Capex CJI3'!$F$124,0)-IF($A11="O7941/2613",'[1]Capex CJI3'!$F$313,0)} -> 164692.23 | H11: 148581.52 | I11: =SUM(F11:H11) -> 392511.75 | J11: =E11+I11 -> 605511.75 | K11: 46265 | L11: {=SUMPRODUCT(('[1]Capex CJI3'!$A$2:$A$433=$A11)*(IFERROR(VALUE('[1]Capex CJI3'!$K$2:$K$433),0)>0)*((ISNUMBER(SEARCH("Reclass internal hours",'[1]Capex CJI3'!$J$2:$J$433)))+((LEN('[1]Capex CJI3'!$E$2:$E$433)>0)*ISERROR(SEARCH("Reclass internal hours",'[1]Capex CJI3'!$J$2:$J$433)))+((LEN('[1]Capex CJI3'!$E$2:$E$433)=0)*ISERROR(SEARCH("Reclass internal hours",'[1]Capex CJI3'!$J$2:$J$433))*ISERROR(SEARCH("WBS Correction",'[1]Capex CJI3'!$J$2:$J$433))*('[1]Capex CJI3'!$D$2:$D$433<>"6405000000"))>0))-IF($A11="O7941/2517",2,0)-IF($A11="O7941/2613",1,0)-IF($A11="O9100/2601",1,0)-IF($A11="O7941/2513",4,0)} -> 30 | M11: {=SUMPRODUCT(('[1]Capex CJI3'!$A$2:$A$433=$A11)*(IFERROR(VALUE('[1]Capex CJI3'!$K$2:$K$433),0)>0)*(LEN('[1]Capex CJI3'!$E$2:$E$433)>0)*ISERROR(SEARCH("Reclass internal hours",'[1]Capex CJI3'!$J$2:$J$433)))-IF($A11="O7941/2517",1,0)-IF($A11="O7941/2613",1,0)} -> 11 | N11: EUR | O11: 928000
A12: O7941/2519 | B12: =SUMIFS('[1]Capex CJI3'!$F$2:$F$433,'[1]Capex CJI3'!$A$2:$A$433,$A12,'[1]Capex CJI3'!$K$2:$K$433,2025,'[1]Capex CJI3'!$J$2:$J$433,"*Reclass internal hours*") -> 38000 | C12: {=SUMPRODUCT(('[1]Capex CJI3'!$A$2:$A$433=$A12)*(IFERROR(VALUE('[1]Capex CJI3'!$K$2:$K$433),0)=2025)*(LEN('[1]Capex CJI3'!$E$2:$E$433)>0)*ISERROR(SEARCH("Reclass internal hours",'[1]Capex CJI3'!$J$2:$J$433))*IFERROR(VALUE('[1]Capex CJI3'!$F$2:$F$433),0))} -> 100000 | D12: {=SUMPRODUCT(('[1]Capex CJI3'!$A$2:$A$433=$A12)*(IFERROR(VALUE('[1]Capex CJI3'!$K$2:$K$433),0)=2025)*(LEN('[1]Capex CJI3'!$E$2:$E$433)=0)*ISERROR(SEARCH("Reclass internal hours",'[1]Capex CJI3'!$J$2:$J$433))*ISERROR(SEARCH("WBS Correction",'[1]Capex CJI3'!$J$2:$J$433))*('[1]Capex CJI3'!$D$2:$D$433<>"6405000000")*IFERROR(VALUE('[1]Capex CJI3'!$F$2:$F$433),0))} -> 0 | E12: =SUM(B12:D12) -> 138000 | F12: =SUMIFS('[1]Capex CJI3'!$F$2:$F$433,'[1]Capex CJI3'!$A$2:$A$433,$A12,'[1]Capex CJI3'!$K$2:$K$433,2026,'[1]Capex CJI3'!$J$2:$J$433,"*Reclass internal hours*") -> 227750.4 | G12: {=SUMPRODUCT(('[1]Capex CJI3'!$A$2:$A$433=$A12)*(IFERROR(VALUE('[1]Capex CJI3'!$K$2:$K$433),0)=2026)*(LEN('[1]Capex CJI3'!$E$2:$E$433)>0)*ISERROR(SEARCH("Reclass internal hours",'[1]Capex CJI3'!$J$2:$J$433))*IFERROR(VALUE('[1]Capex CJI3'!$F$2:$F$433),0))-IF($A12="O7941/2517",'[1]Capex CJI3'!$F$124,0)-IF($A12="O7941/2613",'[1]Capex CJI3'!$F$313,0)} -> 277505.1 | H12: 112698.44 | I12: =SUM(F12:H12) -> 617953.94 | J12: =E12+I12 -> 755953.94 | K12: 46269 | L12: {=SUMPRODUCT(('[1]Capex CJI3'!$A$2:$A$433=$A12)*(IFERROR(VALUE('[1]Capex CJI3'!$K$2:$K$433),0)>0)*((ISNUMBER(SEARCH("Reclass internal hours",'[1]Capex CJI3'!$J$2:$J$433)))+((LEN('[1]Capex CJI3'!$E$2:$E$433)>0)*ISERROR(SEARCH("Reclass internal hours",'[1]Capex CJI3'!$J$2:$J$433)))+((LEN('[1]Capex CJI3'!$E$2:$E$433)=0)*ISERROR(SEARCH("Reclass internal hours",'[1]Capex CJI3'!$J$2:$J$433))*ISERROR(SEARCH("WBS Correction",'[1]Capex CJI3'!$J$2:$J$433))*('[1]Capex CJI3'!$D$2:$D$433<>"6405000000"))>0))-IF($A12="O7941/2517",2,0)-IF($A12="O7941/2613",1,0)-IF($A12="O9100/2601",1,0)-IF($A12="O7941/2513",4,0)} -> 32 | M12: {=SUMPRODUCT(('[1]Capex CJI3'!$A$2:$A$433=$A12)*(IFERROR(VALUE('[1]Capex CJI3'!$K$2:$K$433),0)>0)*(LEN('[1]Capex CJI3'!$E$2:$E$433)>0)*ISERROR(SEARCH("Reclass internal hours",'[1]Capex CJI3'!$J$2:$J$433)))-IF($A12="O7941/2517",1,0)-IF($A12="O7941/2613",1,0)} -> 10 | N12: EUR | O12: 874000
A13: O7941/2523 | B13: =SUMIFS('[1]Capex CJI3'!$F$2:$F$433,'[1]Capex CJI3'!$A$2:$A$433,$A13,'[1]Capex CJI3'!$K$2:$K$433,2025,'[1]Capex CJI3'!$J$2:$J$433,"*Reclass internal hours*") -> 0 | C13: {=SUMPRODUCT(('[1]Capex CJI3'!$A$2:$A$433=$A13)*(IFERROR(VALUE('[1]Capex CJI3'!$K$2:$K$433),0)=2025)*(LEN('[1]Capex CJI3'!$E$2:$E$433)>0)*ISERROR(SEARCH("Reclass internal hours",'[1]Capex CJI3'!$J$2:$J$433))*IFERROR(VALUE('[1]Capex CJI3'!$F$2:$F$433),0))} -> 31990.6 | D13: {=SUMPRODUCT(('[1]Capex CJI3'!$A$2:$A$433=$A13)*(IFERROR(VALUE('[1]Capex CJI3'!$K$2:$K$433),0)=2025)*(LEN('[1]Capex CJI3'!$E$2:$E$433)=0)*ISERROR(SEARCH("Reclass internal hours",'[1]Capex CJI3'!$J$2:$J$433))*ISERROR(SEARCH("WBS Correction",'[1]Capex CJI3'!$J$2:$J$433))*('[1]Capex CJI3'!$D$2:$D$433<>"6405000000")*IFERROR(VALUE('[1]Capex CJI3'!$F$2:$F$433),0))} -> 0 | E13: =SUM(B13:D13) -> 31990.6 | F13: =SUMIFS('[1]Capex CJI3'!$F$2:$F$433,'[1]Capex CJI3'!$A$2:$A$433,$A13,'[1]Capex CJI3'!$K$2:$K$433,2026,'[1]Capex CJI3'!$J$2:$J$433,"*Reclass internal hours*") -> 26009 | G13: {=SUMPRODUCT(('[1]Capex CJI3'!$A$2:$A$433=$A13)*(IFERROR(VALUE('[1]Capex CJI3'!$K$2:$K$433),0)=2026)*(LEN('[1]Capex CJI3'!$E$2:$E$433)>0)*ISERROR(SEARCH("Reclass internal hours",'[1]Capex CJI3'!$J$2:$J$433))*IFERROR(VALUE('[1]Capex CJI3'!$F$2:$F$433),0))-IF($A13="O7941/2517",'[1]Capex CJI3'!$F$124,0)-IF($A13="O7941/2613",'[1]Capex CJI3'!$F$313,0)} -> 39646 | H13: {=SUMPRODUCT(('[1]Capex CJI3'!$A$2:$A$433=$A13)*(IFERROR(VALUE('[1]Capex CJI3'!$K$2:$K$433),0)=2026)*(LEN('[1]Capex CJI3'!$E$2:$E$433)=0)*ISERROR(SEARCH("Reclass internal hours",'[1]Capex CJI3'!$J$2:$J$433))*ISERROR(SEARCH("WBS Correction",'[1]Capex CJI3'!$J$2:$J$433))*('[1]Capex CJI3'!$D$2:$D$433<>"6405000000")*((($A13<>"O7941/2513")+('[1]Capex CJI3'!$D$2:$D$433<>"7405000000")+(IFERROR(VALUE('[1]Capex CJI3'!$L$2:$L$433),0)>=3))>0)*IFERROR(VALUE('[1]Capex CJI3'!$F$2:$F$433),0))-IF($A13="O7941/2517",'[1]Capex CJI3'!$F$132,0)-IF($A13="O9100/2601",'[1]Capex CJI3'!$F$429,0)} -> 0 | I13: =SUM(F13:H13) -> 65655 | J13: =E13+I13 -> 97645.6 | K13: 46255 | L13: {=SUMPRODUCT(('[1]Capex CJI3'!$A$2:$A$433=$A13)*(IFERROR(VALUE('[1]Capex CJI3'!$K$2:$K$433),0)>0)*((ISNUMBER(SEARCH("Reclass internal hours",'[1]Capex CJI3'!$J$2:$J$433)))+((LEN('[1]Capex CJI3'!$E$2:$E$433)>0)*ISERROR(SEARCH("Reclass internal hours",'[1]Capex CJI3'!$J$2:$J$433)))+((LEN('[1]Capex CJI3'!$E$2:$E$433)=0)*ISERROR(SEARCH("Reclass internal hours",'[1]Capex CJI3'!$J$2:$J$433))*ISERROR(SEARCH("WBS Correction",'[1]Capex CJI3'!$J$2:$J$433))*('[1]Capex CJI3'!$D$2:$D$433<>"6405000000"))>0))-IF($A13="O7941/2517",2,0)-IF($A13="O7941/2613",1,0)-IF($A13="O9100/2601",1,0)-IF($A13="O7941/2513",4,0)} -> 7 | M13: {=SUMPRODUCT(('[1]Capex CJI3'!$A$2:$A$433=$A13)*(IFERROR(VALUE('[1]Capex CJI3'!$K$2:$K$433),0)>0)*(LEN('[1]Capex CJI3'!$E$2:$E$433)>0)*ISERROR(SEARCH("Reclass internal hours",'[1]Capex CJI3'!$J$2:$J$433)))-IF($A13="O7941/2517",1,0)-IF($A13="O7941/2613",1,0)} -> 3 | N13: EUR | O13: 119580
A14: O7941/2524 | B14: =SUMIFS('[1]Capex CJI3'!$F$2:$F$433,'[1]Capex CJI3'!$A$2:$A$433,$A14,'[1]Capex CJI3'!$K$2:$K$433,2025,'[1]Capex CJI3'!$J$2:$J$433,"*Reclass internal hours*") -> 0 | C14: {=SUMPRODUCT(('[1]Capex CJI3'!$A$2:$A$433=$A14)*(IFERROR(VALUE('[1]Capex CJI3'!$K$2:$K$433),0)=2025)*(LEN('[1]Capex CJI3'!$E$2:$E$433)>0)*ISERROR(SEARCH("Reclass internal hours",'[1]Capex CJI3'!$J$2:$J$433))*IFERROR(VALUE('[1]Capex CJI3'!$F$2:$F$433),0))} -> 0 | D14: {=SUMPRODUCT(('[1]Capex CJI3'!$A$2:$A$433=$A14)*(IFERROR(VALUE('[1]Capex CJI3'!$K$2:$K$433),0)=2025)*(LEN('[1]Capex CJI3'!$E$2:$E$433)=0)*ISERROR(SEARCH("Reclass internal hours",'[1]Capex CJI3'!$J$2:$J$433))*ISERROR(SEARCH("WBS Correction",'[1]Capex CJI3'!$J$2:$J$433))*('[1]Capex CJI3'!$D$2:$D$433<>"6405000000")*IFERROR(VALUE('[1]Capex CJI3'!$F$2:$F$433),0))} -> 0 | E14: =SUM(B14:D14) -> 0 | F14: =SUMIFS('[1]Capex CJI3'!$F$2:$F$433,'[1]Capex CJI3'!$A$2:$A$433,$A14,'[1]Capex CJI3'!$K$2:$K$433,2026,'[1]Capex CJI3'!$J$2:$J$433,"*Reclass internal hours*") -> 0 | G14: {=SUMPRODUCT(('[1]Capex CJI3'!$A$2:$A$433=$A14)*(IFERROR(VALUE('[1]Capex CJI3'!$K$2:$K$433),0)=2026)*(LEN('[1]Capex CJI3'!$E$2:$E$433)>0)*ISERROR(SEARCH("Reclass internal hours",'[1]Capex CJI3'!$J$2:$J$433))*IFERROR(VALUE('[1]Capex CJI3'!$F$2:$F$433),0))-IF($A14="O7941/2517",'[1]Capex CJI3'!$F$124,0)-IF($A14="O7941/2613",'[1]Capex CJI3'!$F$313,0)} -> 169189 | H14: {=SUMPRODUCT(('[1]Capex CJI3'!$A$2:$A$433=$A14)*(IFERROR(VALUE('[1]Capex CJI3'!$K$2:$K$433),0)=2026)*(LEN('[1]Capex CJI3'!$E$2:$E$433)=0)*ISERROR(SEARCH("Reclass internal hours",'[1]Capex CJI3'!$J$2:$J$433))*ISERROR(SEARCH("WBS Correction",'[1]Capex CJI3'!$J$2:$J$433))*('[1]Capex CJI3'!$D$2:$D$433<>"6405000000")*((($A14<>"O7941/2513")+('[1]Capex CJI3'!$D$2:$D$433<>"7405000000")+(IFERROR(VALUE('[1]Capex CJI3'!$L$2:$L$433),0)>=3))>0)*IFERROR(VALUE('[1]Capex CJI3'!$F$2:$F$433),0))-IF($A14="O7941/2517",'[1]Capex CJI3'!$F$132,0)-IF($A14="O9100/2601",'[1]Capex CJI3'!$F$429,0)} -> 164155 | I14: =SUM(I15:I21) -> 961449.31 | J14: =E14+I14 -> 961449.31 | K14: 46274 | L14: {=SUMPRODUCT(('[1]Capex CJI3'!$A$2:$A$433=$A14)*(IFERROR(VALUE('[1]Capex CJI3'!$K$2:$K$433),0)>0)*((ISNUMBER(SEARCH("Reclass internal hours",'[1]Capex CJI3'!$J$2:$J$433)))+((LEN('[1]Capex CJI3'!$E$2:$E$433)>0)*ISERROR(SEARCH("Reclass internal hours",'[1]Capex CJI3'!$J$2:$J$433)))+((LEN('[1]Capex CJI3'!$E$2:$E$433)=0)*ISERROR(SEARCH("Reclass internal hours",'[1]Capex CJI3'!$J$2:$J$433))*ISERROR(SEARCH("WBS Correction",'[1]Capex CJI3'!$J$2:$J$433))*('[1]Capex CJI3'!$D$2:$D$433<>"6405000000"))>0))-IF($A14="O7941/2517",2,0)-IF($A14="O7941/2613",1,0)-IF($A14="O9100/2601",1,0)-IF($A14="O7941/2513",4,0)} -> 6 | M14: {=SUMPRODUCT(('[1]Capex CJI3'!$A$2:$A$433=$A14)*(IFERROR(VALUE('[1]Capex CJI3'!$K$2:$K$433),0)>0)*(LEN('[1]Capex CJI3'!$E$2:$E$433)>0)*ISERROR(SEARCH("Reclass internal hours",'[1]Capex CJI3'!$J$2:$J$433)))-IF($A14="O7941/2517",1,0)-IF($A14="O7941/2613",1,0)} -> 5 | N14: EUR | O14: 1937717
A15: O7941/2524/1 | B15: =SUMIFS('[1]Capex CJI3'!$F$2:$F$433,'[1]Capex CJI3'!$A$2:$A$433,$A15,'[1]Capex CJI3'!$K$2:$K$433,2025,'[1]Capex CJI3'!$J$2:$J$433,"*Reclass internal hours*") -> 0 | C15: {=SUMPRODUCT(('[1]Capex CJI3'!$A$2:$A$433=$A15)*(IFERROR(VALUE('[1]Capex CJI3'!$K$2:$K$433),0)=2025)*(LEN('[1]Capex CJI3'!$E$2:$E$433)>0)*ISERROR(SEARCH("Reclass internal hours",'[1]Capex CJI3'!$J$2:$J$433))*IFERROR(VALUE('[1]Capex CJI3'!$F$2:$F$433),0))} -> 0 | D15: {=SUMPRODUCT(('[1]Capex CJI3'!$A$2:$A$433=$A15)*(IFERROR(VALUE('[1]Capex CJI3'!$K$2:$K$433),0)=2025)*(LEN('[1]Capex CJI3'!$E$2:$E$433)=0)*ISERROR(SEARCH("Reclass internal hours",'[1]Capex CJI3'!$J$2:$J$433))*ISERROR(SEARCH("WBS Correction",'[1]Capex CJI3'!$J$2:$J$433))*('[1]Capex CJI3'!$D$2:$D$433<>"6405000000")*IFERROR(VALUE('[1]Capex CJI3'!$F$2:$F$433),0))} -> 0 | E15: =SUM(B15:D15) -> 0 | F15: =SUMIFS('[1]Capex CJI3'!$F$2:$F$433,'[1]Capex CJI3'!$A$2:$A$433,$A15,'[1]Capex CJI3'!$K$2:$K$433,2026,'[1]Capex CJI3'!$J$2:$J$433,"*Reclass internal hours*") -> 0 | G15: {=SUMPRODUCT(('[1]Capex CJI3'!$A$2:$A$433=$A15)*(IFERROR(VALUE('[1]Capex CJI3'!$K$2:$K$433),0)=2026)*(LEN('[1]Capex CJI3'!$E$2:$E$433)>0)*ISERROR(SEARCH("Reclass internal hours",'[1]Capex CJI3'!$J$2:$J$433))*IFERROR(VALUE('[1]Capex CJI3'!$F$2:$F$433),0))-IF($A15="O7941/2517",'[1]Capex CJI3'!$F$124,0)-IF($A15="O7941/2613",'[1]Capex CJI3'!$F$313,0)} -> 632000 | H15: {=SUMPRODUCT(('[1]Capex CJI3'!$A$2:$A$433=$A15)*(IFERROR(VALUE('[1]Capex CJI3'!$K$2:$K$433),0)=2026)*(LEN('[1]Capex CJI3'!$E$2:$E$433)=0)*ISERROR(SEARCH("Reclass internal hours",'[1]Capex CJI3'!$J$2:$J$433))*ISERROR(SEARCH("WBS Correction",'[1]Capex CJI3'!$J$2:$J$433))*('[1]Capex CJI3'!$D$2:$D$433<>"6405000000")*((($A15<>"O7941/2513")+('[1]Capex CJI3'!$D$2:$D$433<>"7405000000")+(IFERROR(VALUE('[1]Capex CJI3'!$L$2:$L$433),0)>=3))>0)*IFERROR(VALUE('[1]Capex CJI3'!$F$2:$F$433),0))-IF($A15="O7941/2517",'[1]Capex CJI3'!$F$132,0)-IF($A15="O9100/2601",'[1]Capex CJI3'!$F$429,0)} -> 161000 | I15: =SUM(F15:H15) -> 793000 | J15: =E15+I15 -> 793000 | K15: 46274 | L15: {=SUMPRODUCT(('[1]Capex CJI3'!$A$2:$A$433=$A15)*(IFERROR(VALUE('[1]Capex CJI3'!$K$2:$K$433),0)>0)*((ISNUMBER(SEARCH("Reclass internal hours",'[1]Capex CJI3'!$J$2:$J$433)))+((LEN('[1]Capex CJI3'!$E$2:$E$433)>0)*ISERROR(SEARCH("Reclass internal hours",'[1]Capex CJI3'!$J$2:$J$433)))+((LEN('[1]Capex CJI3'!$E$2:$E$433)=0)*ISERROR(SEARCH("Reclass internal hours",'[1]Capex CJI3'!$J$2:$J$433))*ISERROR(SEARCH("WBS Correction",'[1]Capex CJI3'!$J$2:$J$433))*('[1]Capex CJI3'!$D$2:$D$433<>"6405000000"))>0))-IF($A15="O7941/2517",2,0)-IF($A15="O7941/2613",1,0)-IF($A15="O9100/2601",1,0)-IF($A15="O7941/2513",4,0)} -> 8 | M15: {=SUMPRODUCT(('[1]Capex CJI3'!$A$2:$A$433=$A15)*(IFERROR(VALUE('[1]Capex CJI3'!$K$2:$K$433),0)>0)*(LEN('[1]Capex CJI3'!$E$2:$E$433)>0)*ISERROR(SEARCH("Reclass internal hours",'[1]Capex CJI3'!$J$2:$J$433)))-IF($A15="O7941/2517",1,0)-IF($A15="O7941/2613",1,0)} -> 6 | N15: EUR
A16: O7941/2524/2 | B16: =SUMIFS('[1]Capex CJI3'!$F$2:$F$433,'[1]Capex CJI3'!$A$2:$A$433,$A16,'[1]Capex CJI3'!$K$2:$K$433,2025,'[1]Capex CJI3'!$J$2:$J$433,"*Reclass internal hours*") -> 0 | C16: {=SUMPRODUCT(('[1]Capex CJI3'!$A$2:$A$433=$A16)*(IFERROR(VALUE('[1]Capex CJI3'!$K$2:$K$433),0)=2025)*(LEN('[1]Capex CJI3'!$E$2:$E$433)>0)*ISERROR(SEARCH("Reclass internal hours",'[1]Capex CJI3'!$J$2:$J$433))*IFERROR(VALUE('[1]Capex CJI3'!$F$2:$F$433),0))} -> 0 | D16: {=SUMPRODUCT(('[1]Capex CJI3'!$A$2:$A$433=$A16)*(IFERROR(VALUE('[1]Capex CJI3'!$K$2:$K$433),0)=2025)*(LEN('[1]Capex CJI3'!$E$2:$E$433)=0)*ISERROR(SEARCH("Reclass internal hours",'[1]Capex CJI3'!$J$2:$J$433))*ISERROR(SEARCH("WBS Correction",'[1]Capex CJI3'!$J$2:$J$433))*('[1]Capex CJI3'!$D$2:$D$433<>"6405000000")*IFERROR(VALUE('[1]Capex CJI3'!$F$2:$F$433),0))} -> 0 | E16: =SUM(B16:D16) -> 0 | F16: =SUMIFS('[1]Capex CJI3'!$F$2:$F$433,'[1]Capex CJI3'!$A$2:$A$433,$A16,'[1]Capex CJI3'!$K$2:$K$433,2026,'[1]Capex CJI3'!$J$2:$J$433,"*Reclass internal hours*") -> 0 | G16: {=SUMPRODUCT(('[1]Capex CJI3'!$A$2:$A$433=$A16)*(IFERROR(VALUE('[1]Capex CJI3'!$K$2:$K$433),0)=2026)*(LEN('[1]Capex CJI3'!$E$2:$E$433)>0)*ISERROR(SEARCH("Reclass internal hours",'[1]Capex CJI3'!$J$2:$J$433))*IFERROR(VALUE('[1]Capex CJI3'!$F$2:$F$433),0))-IF($A16="O7941/2517",'[1]Capex CJI3'!$F$124,0)-IF($A16="O7941/2613",'[1]Capex CJI3'!$F$313,0)} -> 74760 | H16: {=SUMPRODUCT(('[1]Capex CJI3'!$A$2:$A$433=$A16)*(IFERROR(VALUE('[1]Capex CJI3'!$K$2:$K$433),0)=2026)*(LEN('[1]Capex CJI3'!$E$2:$E$433)=0)*ISERROR(SEARCH("Reclass internal hours",'[1]Capex CJI3'!$J$2:$J$433))*ISERROR(SEARCH("WBS Correction",'[1]Capex CJI3'!$J$2:$J$433))*('[1]Capex CJI3'!$D$2:$D$433<>"6405000000")*((($A16<>"O7941/2513")+('[1]Capex CJI3'!$D$2:$D$433<>"7405000000")+(IFERROR(VALUE('[1]Capex CJI3'!$L$2:$L$433),0)>=3))>0)*IFERROR(VALUE('[1]Capex CJI3'!$F$2:$F$433),0))-IF($A16="O7941/2517",'[1]Capex CJI3'!$F$132,0)-IF($A16="O9100/2601",'[1]Capex CJI3'!$F$429,0)} -> 14199.99 | I16: =SUM(F16:H16) -> 88959.99 | J16: =E16+I16 -> 88959.99 | K16: 46251 | L16: {=SUMPRODUCT(('[1]Capex CJI3'!$A$2:$A$433=$A16)*(IFERROR(VALUE('[1]Capex CJI3'!$K$2:$K$433),0)>0)*((ISNUMBER(SEARCH("Reclass internal hours",'[1]Capex CJI3'!$J$2:$J$433)))+((LEN('[1]Capex CJI3'!$E$2:$E$433)>0)*ISERROR(SEARCH("Reclass internal hours",'[1]Capex CJI3'!$J$2:$J$433)))+((LEN('[1]Capex CJI3'!$E$2:$E$433)=0)*ISERROR(SEARCH("Reclass internal hours",'[1]Capex CJI3'!$J$2:$J$433))*ISERROR(SEARCH("WBS Correction",'[1]Capex CJI3'!$J$2:$J$433))*('[1]Capex CJI3'!$D$2:$D$433<>"6405000000"))>0))-IF($A16="O7941/2517",2,0)-IF($A16="O7941/2613",1,0)-IF($A16="O9100/2601",1,0)-IF($A16="O7941/2513",4,0)} -> 7 | M16: {=SUMPRODUCT(('[1]Capex CJI3'!$A$2:$A$433=$A16)*(IFERROR(VALUE('[1]Capex CJI3'!$K$2:$K$433),0)>0)*(LEN('[1]Capex CJI3'!$E$2:$E$433)>0)*ISERROR(SEARCH("Reclass internal hours",'[1]Capex CJI3'!$J$2:$J$433)))-IF($A16="O7941/2517",1,0)-IF($A16="O7941/2613",1,0)} -> 6 | N16: EUR
A17: O7941/2524/3 | B17: =SUMIFS('[1]Capex CJI3'!$F$2:$F$433,'[1]Capex CJI3'!$A$2:$A$433,$A17,'[1]Capex CJI3'!$K$2:$K$433,2025,'[1]Capex CJI3'!$J$2:$J$433,"*Reclass internal hours*") -> 0 | C17: {=SUMPRODUCT(('[1]Capex CJI3'!$A$2:$A$433=$A17)*(IFERROR(VALUE('[1]Capex CJI3'!$K$2:$K$433),0)=2025)*(LEN('[1]Capex CJI3'!$E$2:$E$433)>0)*ISERROR(SEARCH("Reclass internal hours",'[1]Capex CJI3'!$J$2:$J$433))*IFERROR(VALUE('[1]Capex CJI3'!$F$2:$F$433),0))} -> 0 | D17: {=SUMPRODUCT(('[1]Capex CJI3'!$A$2:$A$433=$A17)*(IFERROR(VALUE('[1]Capex CJI3'!$K$2:$K$433),0)=2025)*(LEN('[1]Capex CJI3'!$E$2:$E$433)=0)*ISERROR(SEARCH("Reclass internal hours",'[1]Capex CJI3'!$J$2:$J$433))*ISERROR(SEARCH("WBS Correction",'[1]Capex CJI3'!$J$2:$J$433))*('[1]Capex CJI3'!$D$2:$D$433<>"6405000000")*IFERROR(VALUE('[1]Capex CJI3'!$F$2:$F$433),0))} -> 0 | E17: =SUM(B17:D17) -> 0 | F17: =SUMIFS('[1]Capex CJI3'!$F$2:$F$433,'[1]Capex CJI3'!$A$2:$A$433,$A17,'[1]Capex CJI3'!$K$2:$K$433,2026,'[1]Capex CJI3'!$J$2:$J$433,"*Reclass internal hours*") -> 0 | G17: {=SUMPRODUCT(('[1]Capex CJI3'!$A$2:$A$433=$A17)*(IFERROR(VALUE('[1]Capex CJI3'!$K$2:$K$433),0)=2026)*(LEN('[1]Capex CJI3'!$E$2:$E$433)>0)*ISERROR(SEARCH("Reclass internal hours",'[1]Capex CJI3'!$J$2:$J$433))*IFERROR(VALUE('[1]Capex CJI3'!$F$2:$F$433),0))-IF($A17="O7941/2517",'[1]Capex CJI3'!$F$124,0)-IF($A17="O7941/2613",'[1]Capex CJI3'!$F$313,0)} -> 0 | H17: {=SUMPRODUCT(('[1]Capex CJI3'!$A$2:$A$433=$A17)*(IFERROR(VALUE('[1]Capex CJI3'!$K$2:$K$433),0)=2026)*(LEN('[1]Capex CJI3'!$E$2:$E$433)=0)*ISERROR(SEARCH("Reclass internal hours",'[1]Capex CJI3'!$J$2:$J$433))*ISERROR(SEARCH("WBS Correction",'[1]Capex CJI3'!$J$2:$J$433))*('[1]Capex CJI3'!$D$2:$D$433<>"6405000000")*((($A17<>"O7941/2513")+('[1]Capex CJI3'!$D$2:$D$433<>"7405000000")+(IFERROR(VALUE('[1]Capex CJI3'!$L$2:$L$433),0)>=3))>0)*IFERROR(VALUE('[1]Capex CJI3'!$F$2:$F$433),0))-IF($A17="O7941/2517",'[1]Capex CJI3'!$F$132,0)-IF($A17="O9100/2601",'[1]Capex CJI3'!$F$429,0)} -> 11745 | I17: =SUM(F17:H17) -> 11745 | J17: =E17+I17 -> 11745 | K17: 46265 | L17: {=SUMPRODUCT(('[1]Capex CJI3'!$A$2:$A$433=$A17)*(IFERROR(VALUE('[1]Capex CJI3'!$K$2:$K$433),0)>0)*((ISNUMBER(SEARCH("Reclass internal hours",'[1]Capex CJI3'!$J$2:$J$433)))+((LEN('[1]Capex CJI3'!$E$2:$E$433)>0)*ISERROR(SEARCH("Reclass internal hours",'[1]Capex CJI3'!$J$2:$J$433)))+((LEN('[1]Capex CJI3'!$E$2:$E$433)=0)*ISERROR(SEARCH("Reclass internal hours",'[1]Capex CJI3'!$J$2:$J$433))*ISERROR(SEARCH("WBS Correction",'[1]Capex CJI3'!$J$2:$J$433))*('[1]Capex CJI3'!$D$2:$D$433<>"6405000000"))>0))-IF($A17="O7941/2517",2,0)-IF($A17="O7941/2613",1,0)-IF($A17="O9100/2601",1,0)-IF($A17="O7941/2513",4,0)} -> 5 | M17: {=SUMPRODUCT(('[1]Capex CJI3'!$A$2:$A$433=$A17)*(IFERROR(VALUE('[1]Capex CJI3'!$K$2:$K$433),0)>0)*(LEN('[1]Capex CJI3'!$E$2:$E$433)>0)*ISERROR(SEARCH("Reclass internal hours",'[1]Capex CJI3'!$J$2:$J$433)))-IF($A17="O7941/2517",1,0)-IF($A17="O7941/2613",1,0)} -> 0 | N17: EUR
A18: O7941/2524/4 | B18: =SUMIFS('[1]Capex CJI3'!$F$2:$F$433,'[1]Capex CJI3'!$A$2:$A$433,$A18,'[1]Capex CJI3'!$K$2:$K$433,2025,'[1]Capex CJI3'!$J$2:$J$433,"*Reclass internal hours*") -> 0 | C18: {=SUMPRODUCT(('[1]Capex CJI3'!$A$2:$A$433=$A18)*(IFERROR(VALUE('[1]Capex CJI3'!$K$2:$K$433),0)=2025)*(LEN('[1]Capex CJI3'!$E$2:$E$433)>0)*ISERROR(SEARCH("Reclass internal hours",'[1]Capex CJI3'!$J$2:$J$433))*IFERROR(VALUE('[1]Capex CJI3'!$F$2:$F$433),0))} -> 0 | D18: {=SUMPRODUCT(('[1]Capex CJI3'!$A$2:$A$433=$A18)*(IFERROR(VALUE('[1]Capex CJI3'!$K$2:$K$433),0)=2025)*(LEN('[1]Capex CJI3'!$E$2:$E$433)=0)*ISERROR(SEARCH("Reclass internal hours",'[1]Capex CJI3'!$J$2:$J$433))*ISERROR(SEARCH("WBS Correction",'[1]Capex CJI3'!$J$2:$J$433))*('[1]Capex CJI3'!$D$2:$D$433<>"6405000000")*IFERROR(VALUE('[1]Capex CJI3'!$F$2:$F$433),0))} -> 0 | E18: =SUM(B18:D18) -> 0 | F18: =SUMIFS('[1]Capex CJI3'!$F$2:$F$433,'[1]Capex CJI3'!$A$2:$A$433,$A18,'[1]Capex CJI3'!$K$2:$K$433,2026,'[1]Capex CJI3'!$J$2:$J$433,"*Reclass internal hours*") -> 43090 | G18: {=SUMPRODUCT(('[1]Capex CJI3'!$A$2:$A$433=$A18)*(IFERROR(VALUE('[1]Capex CJI3'!$K$2:$K$433),0)=2026)*(LEN('[1]Capex CJI3'!$E$2:$E$433)>0)*ISERROR(SEARCH("Reclass internal hours",'[1]Capex CJI3'!$J$2:$J$433))*IFERROR(VALUE('[1]Capex CJI3'!$F$2:$F$433),0))-IF($A18="O7941/2517",'[1]Capex CJI3'!$F$124,0)-IF($A18="O7941/2613",'[1]Capex CJI3'!$F$313,0)} -> 14062.5 | H18: -14062.5 | I18: =SUM(F18:H18) -> 43090 | J18: =E18+I18 -> 43090 | K18: 46265 | L18: {=SUMPRODUCT(('[1]Capex CJI3'!$A$2:$A$433=$A18)*(IFERROR(VALUE('[1]Capex CJI3'!$K$2:$K$433),0)>0)*((ISNUMBER(SEARCH("Reclass internal hours",'[1]Capex CJI3'!$J$2:$J$433)))+((LEN('[1]Capex CJI3'!$E$2:$E$433)>0)*ISERROR(SEARCH("Reclass internal hours",'[1]Capex CJI3'!$J$2:$J$433)))+((LEN('[1]Capex CJI3'!$E$2:$E$433)=0)*ISERROR(SEARCH("Reclass internal hours",'[1]Capex CJI3'!$J$2:$J$433))*ISERROR(SEARCH("WBS Correction",'[1]Capex CJI3'!$J$2:$J$433))*('[1]Capex CJI3'!$D$2:$D$433<>"6405000000"))>0))-IF($A18="O7941/2517",2,0)-IF($A18="O7941/2613",1,0)-IF($A18="O9100/2601",1,0)-IF($A18="O7941/2513",4,0)} -> 9 | M18: {=SUMPRODUCT(('[1]Capex CJI3'!$A$2:$A$433=$A18)*(IFERROR(VALUE('[1]Capex CJI3'!$K$2:$K$433),0)>0)*(LEN('[1]Capex CJI3'!$E$2:$E$433)>0)*ISERROR(SEARCH("Reclass internal hours",'[1]Capex CJI3'!$J$2:$J$433)))-IF($A18="O7941/2517",1,0)-IF($A18="O7941/2613",1,0)} -> 2 | N18: EUR
A19: O7941/2524/5 | B19: =SUMIFS('[1]Capex CJI3'!$F$2:$F$433,'[1]Capex CJI3'!$A$2:$A$433,$A19,'[1]Capex CJI3'!$K$2:$K$433,2025,'[1]Capex CJI3'!$J$2:$J$433,"*Reclass internal hours*") -> 0 | C19: {=SUMPRODUCT(('[1]Capex CJI3'!$A$2:$A$433=$A19)*(IFERROR(VALUE('[1]Capex CJI3'!$K$2:$K$433),0)=2025)*(LEN('[1]Capex CJI3'!$E$2:$E$433)>0)*ISERROR(SEARCH("Reclass internal hours",'[1]Capex CJI3'!$J$2:$J$433))*IFERROR(VALUE('[1]Capex CJI3'!$F$2:$F$433),0))} -> 0 | D19: {=SUMPRODUCT(('[1]Capex CJI3'!$A$2:$A$433=$A19)*(IFERROR(VALUE('[1]Capex CJI3'!$K$2:$K$433),0)=2025)*(LEN('[1]Capex CJI3'!$E$2:$E$433)=0)*ISERROR(SEARCH("Reclass internal hours",'[1]Capex CJI3'!$J$2:$J$433))*ISERROR(SEARCH("WBS Correction",'[1]Capex CJI3'!$J$2:$J$433))*('[1]Capex CJI3'!$D$2:$D$433<>"6405000000")*IFERROR(VALUE('[1]Capex CJI3'!$F$2:$F$433),0))} -> 0 | E19: =SUM(B19:D19) -> 0 | F19: =SUMIFS('[1]Capex CJI3'!$F$2:$F$433,'[1]Capex CJI3'!$A$2:$A$433,$A19,'[1]Capex CJI3'!$K$2:$K$433,2026,'[1]Capex CJI3'!$J$2:$J$433,"*Reclass internal hours*") -> 0 | G19: {=SUMPRODUCT(('[1]Capex CJI3'!$A$2:$A$433=$A19)*(IFERROR(VALUE('[1]Capex CJI3'!$K$2:$K$433),0)=2026)*(LEN('[1]Capex CJI3'!$E$2:$E$433)>0)*ISERROR(SEARCH("Reclass internal hours",'[1]Capex CJI3'!$J$2:$J$433))*IFERROR(VALUE('[1]Capex CJI3'!$F$2:$F$433),0))-IF($A19="O7941/2517",'[1]Capex CJI3'!$F$124,0)-IF($A19="O7941/2613",'[1]Capex CJI3'!$F$313,0)} -> 2058.59 | H19: {=SUMPRODUCT(('[1]Capex CJI3'!$A$2:$A$433=$A19)*(IFERROR(VALUE('[1]Capex CJI3'!$K$2:$K$433),0)=2026)*(LEN('[1]Capex CJI3'!$E$2:$E$433)=0)*ISERROR(SEARCH("Reclass internal hours",'[1]Capex CJI3'!$J$2:$J$433))*ISERROR(SEARCH("WBS Correction",'[1]Capex CJI3'!$J$2:$J$433))*('[1]Capex CJI3'!$D$2:$D$433<>"6405000000")*((($A19<>"O7941/2513")+('[1]Capex CJI3'!$D$2:$D$433<>"7405000000")+(IFERROR(VALUE('[1]Capex CJI3'!$L$2:$L$433),0)>=3))>0)*IFERROR(VALUE('[1]Capex CJI3'!$F$2:$F$433),0))-IF($A19="O7941/2517",'[1]Capex CJI3'!$F$132,0)-IF($A19="O9100/2601",'[1]Capex CJI3'!$F$429,0)} -> 3155 | I19: =SUM(F19:H19) -> 5213.59 | J19: =E19+I19 -> 5213.59 | K19: 46237 | L19: {=SUMPRODUCT(('[1]Capex CJI3'!$A$2:$A$433=$A19)*(IFERROR(VALUE('[1]Capex CJI3'!$K$2:$K$433),0)>0)*((ISNUMBER(SEARCH("Reclass internal hours",'[1]Capex CJI3'!$J$2:$J$433)))+((LEN('[1]Capex CJI3'!$E$2:$E$433)>0)*ISERROR(SEARCH("Reclass internal hours",'[1]Capex CJI3'!$J$2:$J$433)))+((LEN('[1]Capex CJI3'!$E$2:$E$433)=0)*ISERROR(SEARCH("Reclass internal hours",'[1]Capex CJI3'!$J$2:$J$433))*ISERROR(SEARCH("WBS Correction",'[1]Capex CJI3'!$J$2:$J$433))*('[1]Capex CJI3'!$D$2:$D$433<>"6405000000"))>0))-IF($A19="O7941/2517",2,0)-IF($A19="O7941/2613",1,0)-IF($A19="O9100/2601",1,0)-IF($A19="O7941/2513",4,0)} -> 3 | M19: {=SUMPRODUCT(('[1]Capex CJI3'!$A$2:$A$433=$A19)*(IFERROR(VALUE('[1]Capex CJI3'!$K$2:$K$433),0)>0)*(LEN('[1]Capex CJI3'!$E$2:$E$433)>0)*ISERROR(SEARCH("Reclass internal hours",'[1]Capex CJI3'!$J$2:$J$433)))-IF($A19="O7941/2517",1,0)-IF($A19="O7941/2613",1,0)} -> 2 | N19: EUR
A20: O7941/2524/6 | B20: =SUMIFS('[1]Capex CJI3'!$F$2:$F$433,'[1]Capex CJI3'!$A$2:$A$433,$A20,'[1]Capex CJI3'!$K$2:$K$433,2025,'[1]Capex CJI3'!$J$2:$J$433,"*Reclass internal hours*") -> 0 | C20: {=SUMPRODUCT(('[1]Capex CJI3'!$A$2:$A$433=$A20)*(IFERROR(VALUE('[1]Capex CJI3'!$K$2:$K$433),0)=2025)*(LEN('[1]Capex CJI3'!$E$2:$E$433)>0)*ISERROR(SEARCH("Reclass internal hours",'[1]Capex CJI3'!$J$2:$J$433))*IFERROR(VALUE('[1]Capex CJI3'!$F$2:$F$433),0))} -> 0 | D20: {=SUMPRODUCT(('[1]Capex CJI3'!$A$2:$A$433=$A20)*(IFERROR(VALUE('[1]Capex CJI3'!$K$2:$K$433),0)=2025)*(LEN('[1]Capex CJI3'!$E$2:$E$433)=0)*ISERROR(SEARCH("Reclass internal hours",'[1]Capex CJI3'!$J$2:$J$433))*ISERROR(SEARCH("WBS Correction",'[1]Capex CJI3'!$J$2:$J$433))*('[1]Capex CJI3'!$D$2:$D$433<>"6405000000")*IFERROR(VALUE('[1]Capex CJI3'!$F$2:$F$433),0))} -> 0 | E20: =SUM(B20:D20) -> 0 | F20: =SUMIFS('[1]Capex CJI3'!$F$2:$F$433,'[1]Capex CJI3'!$A$2:$A$433,$A20,'[1]Capex CJI3'!$K$2:$K$433,2026,'[1]Capex CJI3'!$J$2:$J$433,"*Reclass internal hours*") -> 0 | G20: {=SUMPRODUCT(('[1]Capex CJI3'!$A$2:$A$433=$A20)*(IFERROR(VALUE('[1]Capex CJI3'!$K$2:$K$433),0)=2026)*(LEN('[1]Capex CJI3'!$E$2:$E$433)>0)*ISERROR(SEARCH("Reclass internal hours",'[1]Capex CJI3'!$J$2:$J$433))*IFERROR(VALUE('[1]Capex CJI3'!$F$2:$F$433),0))-IF($A20="O7941/2517",'[1]Capex CJI3'!$F$124,0)-IF($A20="O7941/2613",'[1]Capex CJI3'!$F$313,0)} -> 5378.23 | H20: {=SUMPRODUCT(('[1]Capex CJI3'!$A$2:$A$433=$A20)*(IFERROR(VALUE('[1]Capex CJI3'!$K$2:$K$433),0)=2026)*(LEN('[1]Capex CJI3'!$E$2:$E$433)=0)*ISERROR(SEARCH("Reclass internal hours",'[1]Capex CJI3'!$J$2:$J$433))*ISERROR(SEARCH("WBS Correction",'[1]Capex CJI3'!$J$2:$J$433))*('[1]Capex CJI3'!$D$2:$D$433<>"6405000000")*((($A20<>"O7941/2513")+('[1]Capex CJI3'!$D$2:$D$433<>"7405000000")+(IFERROR(VALUE('[1]Capex CJI3'!$L$2:$L$433),0)>=3))>0)*IFERROR(VALUE('[1]Capex CJI3'!$F$2:$F$433),0))-IF($A20="O7941/2517",'[1]Capex CJI3'!$F$132,0)-IF($A20="O9100/2601",'[1]Capex CJI3'!$F$429,0)} -> 0 | I20: =SUM(F20:H20) -> 5378.23 | J20: =E20+I20 -> 5378.23 | K20: 46212 | L20: {=SUMPRODUCT(('[1]Capex CJI3'!$A$2:$A$433=$A20)*(IFERROR(VALUE('[1]Capex CJI3'!$K$2:$K$433),0)>0)*((ISNUMBER(SEARCH("Reclass internal hours",'[1]Capex CJI3'!$J$2:$J$433)))+((LEN('[1]Capex CJI3'!$E$2:$E$433)>0)*ISERROR(SEARCH("Reclass internal hours",'[1]Capex CJI3'!$J$2:$J$433)))+((LEN('[1]Capex CJI3'!$E$2:$E$433)=0)*ISERROR(SEARCH("Reclass internal hours",'[1]Capex CJI3'!$J$2:$J$433))*ISERROR(SEARCH("WBS Correction",'[1]Capex CJI3'!$J$2:$J$433))*('[1]Capex CJI3'!$D$2:$D$433<>"6405000000"))>0))-IF($A20="O7941/2517",2,0)-IF($A20="O7941/2613",1,0)-IF($A20="O9100/2601",1,0)-IF($A20="O7941/2513",4,0)} -> 1 | M20: {=SUMPRODUCT(('[1]Capex CJI3'!$A$2:$A$433=$A20)*(IFERROR(VALUE('[1]Capex CJI3'!$K$2:$K$433),0)>0)*(LEN('[1]Capex CJI3'!$E$2:$E$433)>0)*ISERROR(SEARCH("Reclass internal hours",'[1]Capex CJI3'!$J$2:$J$433)))-IF($A20="O7941/2517",1,0)-IF($A20="O7941/2613",1,0)} -> 1 | N20: EUR
A21: O7941/2524/7 | B21: =SUMIFS('[1]Capex CJI3'!$F$2:$F$433,'[1]Capex CJI3'!$A$2:$A$433,$A21,'[1]Capex CJI3'!$K$2:$K$433,2025,'[1]Capex CJI3'!$J$2:$J$433,"*Reclass internal hours*") -> 0 | C21: {=SUMPRODUCT(('[1]Capex CJI3'!$A$2:$A$433=$A21)*(IFERROR(VALUE('[1]Capex CJI3'!$K$2:$K$433),0)=2025)*(LEN('[1]Capex CJI3'!$E$2:$E$433)>0)*ISERROR(SEARCH("Reclass internal hours",'[1]Capex CJI3'!$J$2:$J$433))*IFERROR(VALUE('[1]Capex CJI3'!$F$2:$F$433),0))} -> 0 | D21: {=SUMPRODUCT(('[1]Capex CJI3'!$A$2:$A$433=$A21)*(IFERROR(VALUE('[1]Capex CJI3'!$K$2:$K$433),0)=2025)*(LEN('[1]Capex CJI3'!$E$2:$E$433)=0)*ISERROR(SEARCH("Reclass internal hours",'[1]Capex CJI3'!$J$2:$J$433))*ISERROR(SEARCH("WBS Correction",'[1]Capex CJI3'!$J$2:$J$433))*('[1]Capex CJI3'!$D$2:$D$433<>"6405000000")*IFERROR(VALUE('[1]Capex CJI3'!$F$2:$F$433),0))} -> 0 | E21: =SUM(B21:D21) -> 0 | F21: =SUMIFS('[1]Capex CJI3'!$F$2:$F$433,'[1]Capex CJI3'!$A$2:$A$433,$A21,'[1]Capex CJI3'!$K$2:$K$433,2026,'[1]Capex CJI3'!$J$2:$J$433,"*Reclass internal hours*") -> 0 | G21: {=SUMPRODUCT(('[1]Capex CJI3'!$A$2:$A$433=$A21)*(IFERROR(VALUE('[1]Capex CJI3'!$K$2:$K$433),0)=2026)*(LEN('[1]Capex CJI3'!$E$2:$E$433)>0)*ISERROR(SEARCH("Reclass internal hours",'[1]Capex CJI3'!$J$2:$J$433))*IFERROR(VALUE('[1]Capex CJI3'!$F$2:$F$433),0))-IF($A21="O7941/2517",'[1]Capex CJI3'!$F$124,0)-IF($A21="O7941/2613",'[1]Capex CJI3'!$F$313,0)} -> 0 | H21: {=SUMPRODUCT(('[1]Capex CJI3'!$A$2:$A$433=$A21)*(IFERROR(VALUE('[1]Capex CJI3'!$K$2:$K$433),0)=2026)*(LEN('[1]Capex CJI3'!$E$2:$E$433)=0)*ISERROR(SEARCH("Reclass internal hours",'[1]Capex CJI3'!$J$2:$J$433))*ISERROR(SEARCH("WBS Correction",'[1]Capex CJI3'!$J$2:$J$433))*('[1]Capex CJI3'!$D$2:$D$433<>"6405000000")*((($A21<>"O7941/2513")+('[1]Capex CJI3'!$D$2:$D$433<>"7405000000")+(IFERROR(VALUE('[1]Capex CJI3'!$L$2:$L$433),0)>=3))>0)*IFERROR(VALUE('[1]Capex CJI3'!$F$2:$F$433),0))-IF($A21="O7941/2517",'[1]Capex CJI3'!$F$132,0)-IF($A21="O9100/2601",'[1]Capex CJI3'!$F$429,0)} -> 14062.5 | I21: =SUM(F21:H21) -> 14062.5 | J21: =E21+I21 -> 14062.5 | K21: 46265 | L21: {=SUMPRODUCT(('[1]Capex CJI3'!$A$2:$A$433=$A21)*(IFERROR(VALUE('[1]Capex CJI3'!$K$2:$K$433),0)>0)*((ISNUMBER(SEARCH("Reclass internal hours",'[1]Capex CJI3'!$J$2:$J$433)))+((LEN('[1]Capex CJI3'!$E$2:$E$433)>0)*ISERROR(SEARCH("Reclass internal hours",'[1]Capex CJI3'!$J$2:$J$433)))+((LEN('[1]Capex CJI3'!$E$2:$E$433)=0)*ISERROR(SEARCH("Reclass internal hours",'[1]Capex CJI3'!$J$2:$J$433))*ISERROR(SEARCH("WBS Correction",'[1]Capex CJI3'!$J$2:$J$433))*('[1]Capex CJI3'!$D$2:$D$433<>"6405000000"))>0))-IF($A21="O7941/2517",2,0)-IF($A21="O7941/2613",1,0)-IF($A21="O9100/2601",1,0)-IF($A21="O7941/2513",4,0)} -> 1 | M21: {=SUMPRODUCT(('[1]Capex CJI3'!$A$2:$A$433=$A21)*(IFERROR(VALUE('[1]Capex CJI3'!$K$2:$K$433),0)>0)*(LEN('[1]Capex CJI3'!$E$2:$E$433)>0)*ISERROR(SEARCH("Reclass internal hours",'[1]Capex CJI3'!$J$2:$J$433)))-IF($A21="O7941/2517",1,0)-IF($A21="O7941/2613",1,0)} -> 0 | N21: EUR
A22: O7941/2603 | B22: =SUMIFS('[1]Capex CJI3'!$F$2:$F$433,'[1]Capex CJI3'!$A$2:$A$433,$A22,'[1]Capex CJI3'!$K$2:$K$433,2025,'[1]Capex CJI3'!$J$2:$J$433,"*Reclass internal hours*") -> 0 | C22: {=SUMPRODUCT(('[1]Capex CJI3'!$A$2:$A$433=$A22)*(IFERROR(VALUE('[1]Capex CJI3'!$K$2:$K$433),0)=2025)*(LEN('[1]Capex CJI3'!$E$2:$E$433)>0)*ISERROR(SEARCH("Reclass internal hours",'[1]Capex CJI3'!$J$2:$J$433))*IFERROR(VALUE('[1]Capex CJI3'!$F$2:$F$433),0))} -> 0 | D22: {=SUMPRODUCT(('[1]Capex CJI3'!$A$2:$A$433=$A22)*(IFERROR(VALUE('[1]Capex CJI3'!$K$2:$K$433),0)=2025)*(LEN('[1]Capex CJI3'!$E$2:$E$433)=0)*ISERROR(SEARCH("Reclass internal hours",'[1]Capex CJI3'!$J$2:$J$433))*ISERROR(SEARCH("WBS Correction",'[1]Capex CJI3'!$J$2:$J$433))*('[1]Capex CJI3'!$D$2:$D$433<>"6405000000")*IFERROR(VALUE('[1]Capex CJI3'!$F$2:$F$433),0))} -> 0 | E22: =SUM(B22:D22) -> 0 | F22: =SUMIFS('[1]Capex CJI3'!$F$2:$F$433,'[1]Capex CJI3'!$A$2:$A$433,$A22,'[1]Capex CJI3'!$K$2:$K$433,2026,'[1]Capex CJI3'!$J$2:$J$433,"*Reclass internal hours*") -> 15650 | G22: {=SUMPRODUCT(('[1]Capex CJI3'!$A$2:$A$433=$A22)*(IFERROR(VALUE('[1]Capex CJI3'!$K$2:$K$433),0)=2026)*(LEN('[1]Capex CJI3'!$E$2:$E$433)>0)*ISERROR(SEARCH("Reclass internal hours",'[1]Capex CJI3'!$J$2:$J$433))*IFERROR(VALUE('[1]Capex CJI3'!$F$2:$F$433),0))-IF($A22="O7941/2517",'[1]Capex CJI3'!$F$124,0)-IF($A22="O7941/2613",'[1]Capex CJI3'!$F$313,0)} -> 84480.53 | H22: -3073 | I22: =SUM(F22:H22) -> 97057.53 | J22: =E22+I22 -> 97057.53 | K22: 46274 | L22: {=SUMPRODUCT(('[1]Capex CJI3'!$A$2:$A$433=$A22)*(IFERROR(VALUE('[1]Capex CJI3'!$K$2:$K$433),0)>0)*((ISNUMBER(SEARCH("Reclass internal hours",'[1]Capex CJI3'!$J$2:$J$433)))+((LEN('[1]Capex CJI3'!$E$2:$E$433)>0)*ISERROR(SEARCH("Reclass internal hours",'[1]Capex CJI3'!$J$2:$J$433)))+((LEN('[1]Capex CJI3'!$E$2:$E$433)=0)*ISERROR(SEARCH("Reclass internal hours",'[1]Capex CJI3'!$J$2:$J$433))*ISERROR(SEARCH("WBS Correction",'[1]Capex CJI3'!$J$2:$J$433))*('[1]Capex CJI3'!$D$2:$D$433<>"6405000000"))>0))-IF($A22="O7941/2517",2,0)-IF($A22="O7941/2613",1,0)-IF($A22="O9100/2601",1,0)-IF($A22="O7941/2513",4,0)} -> 17 | M22: {=SUMPRODUCT(('[1]Capex CJI3'!$A$2:$A$433=$A22)*(IFERROR(VALUE('[1]Capex CJI3'!$K$2:$K$433),0)>0)*(LEN('[1]Capex CJI3'!$E$2:$E$433)>0)*ISERROR(SEARCH("Reclass internal hours",'[1]Capex CJI3'!$J$2:$J$433)))-IF($A22="O7941/2517",1,0)-IF($A22="O7941/2613",1,0)} -> 13 | N22: EUR | O22: =J22 -> 97057.53
